2022-11-07 16:21:10,573 ERROR: Exception on / [GET] [in /home/vlasov/Yandex.Disk/myprojects/microblog/.venv/lib/python3.11/site-packages/flask/app.py:1741]
Traceback (most recent call last):
  File "/home/vlasov/Yandex.Disk/myprojects/microblog/.venv/lib/python3.11/site-packages/sqlalchemy/engine/base.py", line 1900, in _execute_context
    self.dialect.do_execute(
  File "/home/vlasov/Yandex.Disk/myprojects/microblog/.venv/lib/python3.11/site-packages/sqlalchemy/engine/default.py", line 736, in do_execute
    cursor.execute(statement, parameters)
sqlite3.OperationalError: no such table: user

The above exception was the direct cause of the following exception:

Traceback (most recent call last):
  File "/home/vlasov/Yandex.Disk/myprojects/microblog/.venv/lib/python3.11/site-packages/flask/app.py", line 2525, in wsgi_app
    response = self.full_dispatch_request()
               ^^^^^^^^^^^^^^^^^^^^^^^^^^^^
  File "/home/vlasov/Yandex.Disk/myprojects/microblog/.venv/lib/python3.11/site-packages/flask/app.py", line 1822, in full_dispatch_request
    rv = self.handle_user_exception(e)
         ^^^^^^^^^^^^^^^^^^^^^^^^^^^^^
  File "/home/vlasov/Yandex.Disk/myprojects/microblog/.venv/lib/python3.11/site-packages/flask/app.py", line 1818, in full_dispatch_request
    rv = self.preprocess_request()
         ^^^^^^^^^^^^^^^^^^^^^^^^^
  File "/home/vlasov/Yandex.Disk/myprojects/microblog/.venv/lib/python3.11/site-packages/flask/app.py", line 2309, in preprocess_request
    rv = self.ensure_sync(before_func)()
         ^^^^^^^^^^^^^^^^^^^^^^^^^^^^^^^
  File "/home/vlasov/Yandex.Disk/myprojects/microblog/app/routes.py", line 13, in defore_request
    if current_user.is_authenticated:
       ^^^^^^^^^^^^^^^^^^^^^^^^^^^^^
  File "/home/vlasov/Yandex.Disk/myprojects/microblog/.venv/lib/python3.11/site-packages/werkzeug/local.py", line 316, in __get__
    obj = instance._get_current_object()  # type: ignore[misc]
          ^^^^^^^^^^^^^^^^^^^^^^^^^^^^^^
  File "/home/vlasov/Yandex.Disk/myprojects/microblog/.venv/lib/python3.11/site-packages/werkzeug/local.py", line 520, in _get_current_object
    return get_name(local())  # type: ignore
                    ^^^^^^^
  File "/home/vlasov/Yandex.Disk/myprojects/microblog/.venv/lib/python3.11/site-packages/flask_login/utils.py", line 25, in <lambda>
    current_user = LocalProxy(lambda: _get_user())
                                      ^^^^^^^^^^^
  File "/home/vlasov/Yandex.Disk/myprojects/microblog/.venv/lib/python3.11/site-packages/flask_login/utils.py", line 372, in _get_user
    current_app.login_manager._load_user()
  File "/home/vlasov/Yandex.Disk/myprojects/microblog/.venv/lib/python3.11/site-packages/flask_login/login_manager.py", line 364, in _load_user
    user = self._user_callback(user_id)
           ^^^^^^^^^^^^^^^^^^^^^^^^^^^^
  File "/home/vlasov/Yandex.Disk/myprojects/microblog/app/models.py", line 121, in load_user
    return User.query.get(int(id))
           ^^^^^^^^^^^^^^^^^^^^^^^
  File "<string>", line 2, in get
  File "/home/vlasov/Yandex.Disk/myprojects/microblog/.venv/lib/python3.11/site-packages/sqlalchemy/util/deprecations.py", line 402, in warned
    return fn(*args, **kwargs)
           ^^^^^^^^^^^^^^^^^^^
  File "/home/vlasov/Yandex.Disk/myprojects/microblog/.venv/lib/python3.11/site-packages/sqlalchemy/orm/query.py", line 947, in get
    return self._get_impl(ident, loading.load_on_pk_identity)
           ^^^^^^^^^^^^^^^^^^^^^^^^^^^^^^^^^^^^^^^^^^^^^^^^^^
  File "/home/vlasov/Yandex.Disk/myprojects/microblog/.venv/lib/python3.11/site-packages/sqlalchemy/orm/query.py", line 951, in _get_impl
    return self.session._get_impl(
           ^^^^^^^^^^^^^^^^^^^^^^^
  File "/home/vlasov/Yandex.Disk/myprojects/microblog/.venv/lib/python3.11/site-packages/sqlalchemy/orm/session.py", line 2955, in _get_impl
    return db_load_fn(
           ^^^^^^^^^^^
  File "/home/vlasov/Yandex.Disk/myprojects/microblog/.venv/lib/python3.11/site-packages/sqlalchemy/orm/loading.py", line 530, in load_on_pk_identity
    session.execute(
  File "/home/vlasov/Yandex.Disk/myprojects/microblog/.venv/lib/python3.11/site-packages/sqlalchemy/orm/session.py", line 1714, in execute
    result = conn._execute_20(statement, params or {}, execution_options)
             ^^^^^^^^^^^^^^^^^^^^^^^^^^^^^^^^^^^^^^^^^^^^^^^^^^^^^^^^^^^^
  File "/home/vlasov/Yandex.Disk/myprojects/microblog/.venv/lib/python3.11/site-packages/sqlalchemy/engine/base.py", line 1705, in _execute_20
    return meth(self, args_10style, kwargs_10style, execution_options)
           ^^^^^^^^^^^^^^^^^^^^^^^^^^^^^^^^^^^^^^^^^^^^^^^^^^^^^^^^^^^
  File "/home/vlasov/Yandex.Disk/myprojects/microblog/.venv/lib/python3.11/site-packages/sqlalchemy/sql/elements.py", line 333, in _execute_on_connection
    return connection._execute_clauseelement(
           ^^^^^^^^^^^^^^^^^^^^^^^^^^^^^^^^^^
  File "/home/vlasov/Yandex.Disk/myprojects/microblog/.venv/lib/python3.11/site-packages/sqlalchemy/engine/base.py", line 1572, in _execute_clauseelement
    ret = self._execute_context(
          ^^^^^^^^^^^^^^^^^^^^^^
  File "/home/vlasov/Yandex.Disk/myprojects/microblog/.venv/lib/python3.11/site-packages/sqlalchemy/engine/base.py", line 1943, in _execute_context
    self._handle_dbapi_exception(
  File "/home/vlasov/Yandex.Disk/myprojects/microblog/.venv/lib/python3.11/site-packages/sqlalchemy/engine/base.py", line 2124, in _handle_dbapi_exception
    util.raise_(
  File "/home/vlasov/Yandex.Disk/myprojects/microblog/.venv/lib/python3.11/site-packages/sqlalchemy/util/compat.py", line 208, in raise_
    raise exception
  File "/home/vlasov/Yandex.Disk/myprojects/microblog/.venv/lib/python3.11/site-packages/sqlalchemy/engine/base.py", line 1900, in _execute_context
    self.dialect.do_execute(
  File "/home/vlasov/Yandex.Disk/myprojects/microblog/.venv/lib/python3.11/site-packages/sqlalchemy/engine/default.py", line 736, in do_execute
    cursor.execute(statement, parameters)
sqlalchemy.exc.OperationalError: (sqlite3.OperationalError) no such table: user
[SQL: SELECT user.id AS user_id, user.username AS user_username, user.email AS user_email, user.password_hash AS user_password_hash, user.about_me AS user_about_me, user.last_seen AS user_last_seen 
FROM user 
WHERE user.id = ?]
[parameters: (1,)]
(Background on this error at: https://sqlalche.me/e/14/e3q8)
2022-11-07 16:24:28,991 INFO: Microblog startup [in /home/vlasov/Yandex.Disk/myprojects/microblog/app/__init__.py:50]
2022-11-07 16:25:44,962 INFO: Microblog startup [in /home/vlasov/Yandex.Disk/myprojects/microblog/app/__init__.py:50]
2022-11-07 16:25:56,586 INFO: Microblog startup [in /home/vlasov/Yandex.Disk/myprojects/microblog/app/__init__.py:50]
2022-11-07 16:26:30,570 INFO: Microblog startup [in /home/vlasov/Yandex.Disk/myprojects/microblog/app/__init__.py:50]
2022-11-07 16:26:38,207 INFO: Microblog startup [in /home/vlasov/Yandex.Disk/myprojects/microblog/app/__init__.py:50]
2022-11-07 16:39:01,195 INFO: Microblog startup [in /home/vlasov/Yandex.Disk/myprojects/microblog/app/__init__.py:50]
2022-11-07 16:39:42,366 INFO: Microblog startup [in /home/vlasov/Yandex.Disk/myprojects/microblog/app/__init__.py:50]
2022-11-07 16:39:47,579 INFO: Microblog startup [in /home/vlasov/Yandex.Disk/myprojects/microblog/app/__init__.py:50]
2022-11-07 16:39:50,824 INFO: Microblog startup [in /home/vlasov/Yandex.Disk/myprojects/microblog/app/__init__.py:50]
2022-11-07 16:45:56,948 ERROR: Exception on /follow/susan [GET] [in /home/vlasov/Yandex.Disk/myprojects/microblog/.venv/lib/python3.11/site-packages/flask/app.py:1741]
Traceback (most recent call last):
  File "/home/vlasov/Yandex.Disk/myprojects/microblog/.venv/lib/python3.11/site-packages/flask/app.py", line 2525, in wsgi_app
    response = self.full_dispatch_request()
               ^^^^^^^^^^^^^^^^^^^^^^^^^^^^
  File "/home/vlasov/Yandex.Disk/myprojects/microblog/.venv/lib/python3.11/site-packages/flask/app.py", line 1822, in full_dispatch_request
    rv = self.handle_user_exception(e)
         ^^^^^^^^^^^^^^^^^^^^^^^^^^^^^
  File "/home/vlasov/Yandex.Disk/myprojects/microblog/.venv/lib/python3.11/site-packages/flask/app.py", line 1820, in full_dispatch_request
    rv = self.dispatch_request()
         ^^^^^^^^^^^^^^^^^^^^^^^
  File "/home/vlasov/Yandex.Disk/myprojects/microblog/.venv/lib/python3.11/site-packages/flask/app.py", line 1796, in dispatch_request
    return self.ensure_sync(self.view_functions[rule.endpoint])(**view_args)
           ^^^^^^^^^^^^^^^^^^^^^^^^^^^^^^^^^^^^^^^^^^^^^^^^^^^^^^^^^^^^^^^^^
  File "/home/vlasov/Yandex.Disk/myprojects/microblog/.venv/lib/python3.11/site-packages/flask_login/utils.py", line 290, in decorated_view
    return current_app.ensure_sync(func)(*args, **kwargs)
           ^^^^^^^^^^^^^^^^^^^^^^^^^^^^^^^^^^^^^^^^^^^^^^
  File "/home/vlasov/Yandex.Disk/myprojects/microblog/app/routes.py", line 130, in follow
    return redirect('user', username=username)
           ^^^^^^^^^^^^^^^^^^^^^^^^^^^^^^^^^^^
TypeError: redirect() got an unexpected keyword argument 'username'
2022-11-07 16:50:55,366 INFO: Microblog startup [in /home/vlasov/Yandex.Disk/myprojects/microblog/app/__init__.py:50]
2022-11-07 16:54:19,117 INFO: Microblog startup [in /home/vlasov/Yandex.Disk/myprojects/microblog/app/__init__.py:50]
2022-11-07 16:55:15,694 INFO: Microblog startup [in /home/vlasov/Yandex.Disk/myprojects/microblog/app/__init__.py:50]
2022-11-07 16:55:50,275 INFO: Microblog startup [in /home/vlasov/Yandex.Disk/myprojects/microblog/app/__init__.py:50]
2022-11-07 18:23:48,504 INFO: Microblog startup [in /home/vlasov/Yandex.Disk/myprojects/microblog/app/__init__.py:50]
2022-11-07 18:24:10,455 INFO: Microblog startup [in /home/vlasov/Yandex.Disk/myprojects/microblog/app/__init__.py:50]
2022-11-07 18:26:12,528 INFO: Microblog startup [in /home/vlasov/Yandex.Disk/myprojects/microblog/app/__init__.py:50]
2022-11-07 18:26:30,524 INFO: Microblog startup [in /home/vlasov/Yandex.Disk/myprojects/microblog/app/__init__.py:50]
